Workbook

Sheet Responses
A1: submitted_at | B1: contact_name | C1: contact_phone | D1: contact_email | E1: branch | F1: service_requested | G1: language | H1: source | I1: ces_find_channel | J1: ces_easy_handle | K1: resolution | L1: nps_score | M1: nps_reason | N1: csat_overall | O1: csat_as_advertised | P1: csat_expectations | Q1: csat_rep_knowledge | R1: csat_communication | S1: csat_response_time | T1: ces_avg | U1: csat_avg | V1: nps_category | W1: is_flagged | X1: followed_up_at | Y1: follow_up_notes
A2: 46204.356 | B2: Noura Al Kaabi | C2: +971 52 000 0001 | D2: noura.al.kaabi1@example.com | E2: Dubai | F2: oil_change | G2: en | H2: qr | I2: 5 | J2: 5 | K2: yes | L2: 10 | M2: The whole process was easy — booking online, dropping the car, paying by card. | N2: 4 | O2: 4 | P2: 5 | Q2: 5 | R2: 5 | S2: 5 | T2: =ROUND(AVERAGE(I2:J2),2) | U2: =ROUND(AVERAGE(N2:S2),2) | V2: =IF(L2>=9,"promoter",IF(L2>=7,"passive","detractor")) | W2: =IF(OR(V2="detractor",K2<>"yes"),1,0)
A3: 46204.376 | B3: Hind Al Balushi | C3: +971 50 000 0002 | D3: hind.al.balushi2@example.com | E3: Sharjah | F3: brake_repair | G3: en | H3: link | I3: 5 | J3: 4 | K3: yes | L3: 9 | M3: Quoted price was the final price. No surprises on the invoice after the brake job. | N3: 4 | O3: 5 | P3: 5 | Q3: 5 | R3: 5 | S3: 5 | T3: =ROUND(AVERAGE(I3:J3),2) | U3: =ROUND(AVERAGE(N3:S3),2) | V3: =IF(L3>=9,"promoter",IF(L3>=7,"passive","detractor")) | W3: =IF(OR(V3="detractor",K3<>"yes"),1,0)
A4: 46204.392 | B4: Ariel Malik | C4: +971 54 000 0003 | D4: ariel.malik3@example.com | E4: Abu Dhabi | F4: oil_change | G4: en | H4: link | I4: 4 | J4: 4 | K4: partially | L4: 8 | M4: Average experience. Nothing went wrong, nothing stood out either. | N4: 4 | O4: 4 | P4: 4 | Q4: 5 | R4: 5 | S4: 4 | T4: =ROUND(AVERAGE(I4:J4),2) | U4: =ROUND(AVERAGE(N4:S4),2) | V4: =IF(L4>=9,"promoter",IF(L4>=7,"passive","detractor")) | W4: =IF(OR(V4="detractor",K4<>"yes"),1,0) | X4: 46206.351 | Y4: Called and apologised. Technician who handled the job was briefed by the workshop supervisor.
A5: 46204.426 | B5: Faisal Kamau | C5: +971 56 000 0004 | D5: faisal.kamau4@example.com | E5: Al Ain | F5: diagnostic | G5: ar | H5: link | I5: 1 | J5: 1 | K5: yes | L5: 2 | M5: لم يتم حل المشكلة بشكل كامل ولم يتواصل معي أحد. | N5: 1 | O5: 2 | P5: 1 | Q5: 1 | R5: 1 | S5: 1 | T5: =ROUND(AVERAGE(I5:J5),2) | U5: =ROUND(AVERAGE(N5:S5),2) | V5: =IF(L5>=9,"promoter",IF(L5>=7,"passive","detractor")) | W5: =IF(OR(V5="detractor",K5<>"yes"),1,0) | X5: 46205.801 | Y5: Called and apologised. Technician who handled the job was briefed by the workshop supervisor.
A6: 46204.429 | B6: Amal Whitfield | C6: +971 54 000 0005 | D6: amal.whitfield5@example.com | E6: Dubai | F6: general_maintenance | G6: en | H6: staff | I6: 3 | J6: 3 | K6: partially | L6: 8 | M6: Good workmanship. Communication could be better — I had to call twice for an update. | N6: 4 | O6: 5 | P6: 3 | Q6: 4 | R6: 5 | S6: 4 | T6: =ROUND(AVERAGE(I6:J6),2) | U6: =ROUND(AVERAGE(N6:S6),2) | V6: =IF(L6>=9,"promoter",IF(L6>=7,"passive","detractor")) | W6: =IF(OR(V6="detractor",K6<>"yes"),1,0) | X6: 46204.762 | Y6: Discussed the quote variance with the customer; the extra labour line was waived.
A7: 46204.491 | B7: Rashid Aquino | C7: +971 50 000 0006 | D7: rashid.aquino6@example.com | E7: Dubai | F7: oil_change | G7: en | H7: link | I7: 4 | J7: 3 | K7: partially | L7: 8 | M7: Reasonable service. I would like a clearer breakdown of labour versus parts on the invoice. | N7: 5 | O7: 4 | P7: 4 | Q7: 5 | R7: 3 | S7: 4 | T7: =ROUND(AVERAGE(I7:J7),2) | U7: =ROUND(AVERAGE(N7:S7),2) | V7: =IF(L7>=9,"promoter",IF(L7>=7,"passive","detractor")) | W7: =IF(OR(V7="detractor",K7<>"yes"),1,0) | X7: 46206.741 | Y7: Called and apologised. Technician who handled the job was briefed by the workshop supervisor.
A8: 46204.609 | B8: Yousef Mendoza | C8: +971 52 000 0007 | D8: yousef.mendoza7@example.com | E8: Sharjah | F8: general_maintenance | G8: en | H8: link | I8: 4 | J8: 5 | K8: yes | L8: 10 | M8: They followed up a week later to check the car was still running well. | N8: 5 | O8: 4 | P8: 5 | Q8: 5 | R8: 5 | S8: 5 | T8: =ROUND(AVERAGE(I8:J8),2) | U8: =ROUND(AVERAGE(N8:S8),2) | V8: =IF(L8>=9,"promoter",IF(L8>=7,"passive","detractor")) | W8: =IF(OR(V8="detractor",K8<>"yes"),1,0)
A9: 46204.684 | B9: Rajesh Harrison | C9: +971 58 000 0008 | D9: rajesh.harrison8@example.com | E9: Abu Dhabi | F9: general_maintenance | G9: en | H9: link | I9: 2 | J9: 3 | K9: partially | L9: 4 | M9: They could not diagnose the fault and still charged me the full inspection fee. | N9: 3 | O9: 2 | P9: 2 | Q9: 3 | R9: 2 | S9: 1 | T9: =ROUND(AVERAGE(I9:J9),2) | U9: =ROUND(AVERAGE(N9:S9),2) | V9: =IF(L9>=9,"promoter",IF(L9>=7,"passive","detractor")) | W9: =IF(OR(V9="detractor",K9<>"yes"),1,0)
A10: 46204.789 | B10: Manoj Kamau | C10: +971 54 000 0009 | D10: manoj.kamau9@example.com | E10: Dubai | F10: transmission | G10: en | H10: portal | I10: 4 | J10: 5 | K10: yes | L10: 10 | M10: They sent me photos of the old parts before replacing anything. That kind of transparency is rare. | N10: 5 | O10: 5 | P10: 5 | Q10: 5 | R10: 5 | S10: 5 | T10: =ROUND(AVERAGE(I10:J10),2) | U10: =ROUND(AVERAGE(N10:S10),2) | V10: =IF(L10>=9,"promoter",IF(L10>=7,"passive","detractor")) | W10: =IF(OR(V10="detractor",K10<>"yes"),1,0)
A11: 46205.35 | B11: Michael Reddy | C11: +971 50 000 0010 | D11: michael.reddy10@example.com | E11: Dubai | F11: brake_repair | G11: ar | H11: link | I11: 3 | J11: 1 | K11: no | L11: 5 | M11: لم يتم حل المشكلة بشكل كامل ولم يتواصل معي أحد. | N11: 2 | O11: 1 | P11: 1 | Q11: 3 | R11: 3 | S11: 1 | T11: =ROUND(AVERAGE(I11:J11),2) | U11: =ROUND(AVERAGE(N11:S11),2) | V11: =IF(L11>=9,"promoter",IF(L11>=7,"passive","detractor")) | W11: =IF(OR(V11="detractor",K11<>"yes"),1,0) | X11: 46206.641 | Y11: Followed up by phone. Customer declined a return visit but accepted the apology.
A12: 46205.391 | B12: Salma Al Zaabi | C12: +971 55 000 0011 | D12: salma.al.zaabi11@example.com | E12: Sharjah | F12: general_maintenance | G12: en | H12: link | I12: 4 | J12: 4 | K12: yes | L12: 7 | M12: Fine service, though I was not told about an extra charge until I came to pay. | N12: 3 | O12: 3 | P12: 3 | Q12: 2 | R12: 2 | S12: 3 | T12: =ROUND(AVERAGE(I12:J12),2) | U12: =ROUND(AVERAGE(N12:S12),2) | V12: =IF(L12>=9,"promoter",IF(L12>=7,"passive","detractor")) | W12: =IF(OR(V12="detractor",K12<>"yes"),1,0)
A13: 46205.436 | B13: Marife Al Blooshi | C13: +971 50 000 0012 | D13: marife.al.blooshi12@example.com | E13: Abu Dhabi | F13: brake_repair | G13: en | H13: link | I13: 4 | J13: 4 | K13: yes | L13: 9 | M13: Good warranty on the parts and they registered it for me without being asked. | N13: 5 | O13: 5 | P13: 5 | Q13: 5 | R13: 4 | S13: 4 | T13: =ROUND(AVERAGE(I13:J13),2) | U13: =ROUND(AVERAGE(N13:S13),2) | V13: =IF(L13>=9,"promoter",IF(L13>=7,"passive","detractor")) | W13: =IF(OR(V13="detractor",K13<>"yes"),1,0)
A14: 46205.439 | B14: Manoj Mensah | C14: +971 52 000 0013 | D14: manoj.mensah13@example.com | E14: Abu Dhabi | F14: general_maintenance | G14: en | H14: link | I14: 5 | J14: 4 | K14: yes | L14: 9 | M14: Straightforward, no upselling, and the routine service was completed a day early. | N14: 5 | O14: 5 | P14: 5 | Q14: 5 | R14: 5 | S14: 5 | T14: =ROUND(AVERAGE(I14:J14),2) | U14: =ROUND(AVERAGE(N14:S14),2) | V14: =IF(L14>=9,"promoter",IF(L14>=7,"passive","detractor")) | W14: =IF(OR(V14="detractor",K14<>"yes"),1,0)
A15: 46205.462 | B15: Adnan Chandran | C15: +971 55 000 0014 | D15: adnan.chandran14@example.com | E15: Sharjah | F15: engine_repair | G15: en | H15: link | I15: 4 | J15: 4 | K15: yes | L15: 10 | M15: Very satisfied — the invoice was itemised and every line was explained. | N15: 4 | O15: 5 | P15: 5 | Q15: 4 | R15: 5 | S15: 4 | T15: =ROUND(AVERAGE(I15:J15),2) | U15: =ROUND(AVERAGE(N15:S15),2) | V15: =IF(L15>=9,"promoter",IF(L15>=7,"passive","detractor")) | W15: =IF(OR(V15="detractor",K15<>"yes"),1,0)
A16: 46205.479 | B16: Vinu Mathew | C16: +971 50 000 0015 | D16: vinu.mathew15@example.com | E16: Dubai | F16: tire_service | G16: en | H16: link | I16: 4 | J16: 5 | K16: yes | L16: 9 | M16: I have been coming here for three years. the tyre work is always done right the first time. | N16: 3 | O16: 3 | P16: 4 | Q16: 3 | R16: 4 | S16: 4 | T16: =ROUND(AVERAGE(I16:J16),2) | U16: =ROUND(AVERAGE(N16:S16),2) | V16: =IF(L16>=9,"promoter",IF(L16>=7,"passive","detractor")) | W16: =IF(OR(V16="detractor",K16<>"yes"),1,0)
A17: 46205.758 | B17: Shalini Al Mansoori | C17: +971 58 000 0016 | D17: shalini.al.mansoori16@example.com | E17: Sharjah | F17: general_maintenance | G17: en | H17: staff | I17: 4 | J17: 5 | K17: yes | L17: 10 | M17: Best experience I have had with a garage in the UAE. the routine service done properly and on budget. | N17: 5 | O17: 5 | P17: 4 | Q17: 5 | R17: 4 | S17: 4 | T17: =ROUND(AVERAGE(I17:J17),2) | U17: =ROUND(AVERAGE(N17:S17),2) | V17: =IF(L17>=9,"promoter",IF(L17>=7,"passive","detractor")) | W17: =IF(OR(V17="detractor",K17<>"yes"),1,0)
A18: 46205.87 | B18: Fatima Al Yammahi | C18: +971 58 000 0017 | D18: fatima.al.yammahi17@example.com | E18: Al Ain | F18: tire_service | G18: en | H18: link | I18: 5 | J18: 4 | K18: yes | L18: 9 | M18: The service advisor explained exactly what the tyre work needed and what could wait. No pressure to spend more. | N18: 4 | O18: 5 | P18: 4 | Q18: 5 | R18: 5 | S18: 4 | T18: =ROUND(AVERAGE(I18:J18),2) | U18: =ROUND(AVERAGE(N18:S18),2) | V18: =IF(L18>=9,"promoter",IF(L18>=7,"passive","detractor")) | W18: =IF(OR(V18="detractor",K18<>"yes"),1,0)
A19: 46206.485 | B19: Abdulla Mensah | C19: +971 54 000 0018 | D19: abdulla.mensah18@example.com | E19: Sharjah | F19: bodywork | G19: ar | H19: link | I19: 4 | J19: 3 | K19: yes | L19: 7 | M19: العمل جيد لكن الانتظار كان أطول من المتوقع. | N19: 4 | O19: 4 | P19: 4 | Q19: 3 | R19: 5 | S19: 3 | T19: =ROUND(AVERAGE(I19:J19),2) | U19: =ROUND(AVERAGE(N19:S19),2) | V19: =IF(L19>=9,"promoter",IF(L19>=7,"passive","detractor")) | W19: =IF(OR(V19="detractor",K19<>"yes"),1,0)
A20: 46206.706 | B20: Tariq Al Hosani | C20: +971 52 000 0019 | D20: tariq.al.hosani19@example.com | E20: Sharjah | F20: bodywork | G20: ar | H20: qr | I20: 2 | J20: 2 | K20: no | L20: 3 | M20: نفس المشكلة عادت بعد أسبوع واحد واضطررت للرجوع مرة أخرى. | N20: 3 | O20: 2 | P20: 1 | Q20: 2 | R20: 2 | S20: 3 | T20: =ROUND(AVERAGE(I20:J20),2) | U20: =ROUND(AVERAGE(N20:S20),2) | V20: =IF(L20>=9,"promoter",IF(L20>=7,"passive","detractor")) | W20: =IF(OR(V20="detractor",K20<>"yes"),1,0) | X20: 46208.664 | Y20: Arranged collection of the vehicle at our cost to re-inspect the complaint.
A21: 46206.789 | B21: Hamad Rehman | C21: +971 56 000 0020 | D21: hamad.rehman20@example.com | E21: Al Ain | F21: general_maintenance | G21: en | H21: link | I21: 1 | J21: 1 | K21: partially | L21: 5 | M21: the routine service was not completed properly and I had to go elsewhere to have it corrected. | N21: 3 | O21: 3 | P21: 2 | Q21: 3 | R21: 1 | S21: 3 | T21: =ROUND(AVERAGE(I21:J21),2) | U21: =ROUND(AVERAGE(N21:S21),2) | V21: =IF(L21>=9,"promoter",IF(L21>=7,"passive","detractor")) | W21: =IF(OR(V21="detractor",K21<>"yes"),1,0)
A22: 46207.401 | B22: Naveen Sharma | C22: +971 54 000 0021 | D22: naveen.sharma21@example.com | E22: Dubai | F22: general_maintenance | G22: en | H22: qr | I22: 5 | J22: 5 | K22: yes | L22: 9 | M22: They diagnosed in an hour what two other workshops could not find in a week. | N22: 4 | O22: 5 | P22: 5 | Q22: 5 | R22: 5 | S22: 5 | T22: =ROUND(AVERAGE(I22:J22),2) | U22: =ROUND(AVERAGE(N22:S22),2) | V22: =IF(L22>=9,"promoter",IF(L22>=7,"passive","detractor")) | W22: =IF(OR(V22="detractor",K22<>"yes"),1,0)
A23: 46207.401 | B23: Abdulla Al Kaabi | C23: +971 50 000 0022 | D23: abdulla.al.kaabi22@example.com | E23: Abu Dhabi | F23: oil_change | G23: en | H23: portal | I23: 4 | J23: 3 | K23: yes | L23: 8 | M23: Happy with the outcome, less happy with the hour I spent waiting to hand over the keys. | N23: 3 | O23: 3 | P23: 2 | Q23: 2 | R23: 2 | S23: 3 | T23: =ROUND(AVERAGE(I23:J23),2) | U23: =ROUND(AVERAGE(N23:S23),2) | V23: =IF(L23>=9,"promoter",IF(L23>=7,"passive","detractor")) | W23: =IF(OR(V23="detractor",K23<>"yes"),1,0)
A24: 46207.485 | B24: Ariel Al Nuaimi | C24: +971 55 000 0023 | D24: ariel.al.nuaimi23@example.com | E24: Sharjah | F24: oil_change | G24: en | H24: link | I24: 5 | J24: 5 | K24: yes | L24: 10 | M24: Very professional from the first call to handover. Nothing to complain about. | N24: 4 | O24: 4 | P24: 4 | Q24: 4 | R24: 3 | S24: 3 | T24: =ROUND(AVERAGE(I24:J24),2) | U24: =ROUND(AVERAGE(N24:S24),2) | V24: =IF(L24>=9,"promoter",IF(L24>=7,"passive","detractor")) | W24: =IF(OR(V24="detractor",K24<>"yes"),1,0)
A25: 46207.496 | B25: Yousef Aquino | C25: +971 56 000 0024 | D25: yousef.aquino24@example.com | E25: Sharjah | F25: bodywork | G25: en | H25: portal | I25: 4 | J25: 4 | K25: partially | L25: 8 | M25: Work was correct but it took two visits to sort out completely. | N25: 4 | O25: 5 | P25: 3 | Q25: 5 | R25: 4 | S25: 5 | T25: =ROUND(AVERAGE(I25:J25),2) | U25: =ROUND(AVERAGE(N25:S25),2) | V25: =IF(L25>=9,"promoter",IF(L25>=7,"passive","detractor")) | W25: =IF(OR(V25="detractor",K25<>"yes"),1,0)
A26: 46207.567 | B26: Thomas Rehman | C26: +971 56 000 0025 | D26: thomas.rehman25@example.com | E26: Sharjah | F26: tire_service | G26: en | H26: link | I26: 2 | J26: 2 | K26: partially | L26: 6 | M26: Told me the job was done, but the noise I brought it in for is unchanged. | N26: 3 | O26: 3 | P26: 4 | Q26: 2 | R26: 3 | S26: 4 | T26: =ROUND(AVERAGE(I26:J26),2) | U26: =ROUND(AVERAGE(N26:S26),2) | V26: =IF(L26>=9,"promoter",IF(L26>=7,"passive","detractor")) | W26: =IF(OR(V26="detractor",K26<>"yes"),1,0) | X26: 46208.65 | Y26: Customer confirmed the repeat fault was fixed on the return visit and is satisfied now.
A27: 46207.652 | B27: Usman Al Nuaimi | C27: +971 50 000 0026 | D27: usman.al.nuaimi26@example.com | E27: Al Ain | F27: transmission | G27: en | H27: link | I27: 5 | J27: 5 | K27: yes | L27: 10 | M27: Staff are polite and the workmanship on the gearbox work is solid. No issues since. | N27: 5 | O27: 4 | P27: 4 | Q27: 5 | R27: 5 | S27: 5 | T27: =ROUND(AVERAGE(I27:J27),2) | U27: =ROUND(AVERAGE(N27:S27),2) | V27: =IF(L27>=9,"promoter",IF(L27>=7,"passive","detractor")) | W27: =IF(OR(V27="detractor",K27<>"yes"),1,0)
A28: 46207.68 | B28: David Iqbal | C28: +971 50 000 0027 | D28: david.iqbal27@example.com | E28: Abu Dhabi | F28: diagnostic | G28: en | H28: link | I28: 4 | J28: 4 | K28: yes | L28: 8 | M28: Good technical work. The paperwork at collection took much longer than it needed to. | N28: 4 | O28: 3 | P28: 4 | Q28: 4 | R28: 4 | S28: 4 | T28: =ROUND(AVERAGE(I28:J28),2) | U28: =ROUND(AVERAGE(N28:S28),2) | V28: =IF(L28>=9,"promoter",IF(L28>=7,"passive","detractor")) | W28: =IF(OR(V28="detractor",K28<>"yes"),1,0)
A29: 46207.69 | B29: Naeem Malik | C29: +971 58 000 0028 | D29: naeem.malik28@example.com | E29: Abu Dhabi | F29: general_maintenance | G29: en | H29: link | I29: 4 | J29: 3 | K29: partially | L29: 7 | M29: They fixed it, but the first estimate and the second estimate were quite different. | N29: 4 | O29: 4 | P29: 4 | Q29: 4 | R29: 2 | S29: 3 | T29: =ROUND(AVERAGE(I29:J29),2) | U29: =ROUND(AVERAGE(N29:S29),2) | V29: =IF(L29>=9,"promoter",IF(L29>=7,"passive","detractor")) | W29: =IF(OR(V29="detractor",K29<>"yes"),1,0) | X29: 46207.815 | Y29: Reached the customer on the second attempt. Car brought back in and the fault rectified under warranty.
A30: 46207.705 | B30: Mohammed Pillai | C30: +971 58 000 0029 | D30: mohammed.pillai29@example.com | E30: Al Ain | F30: brake_repair | G30: en | H30: link | I30: 4 | J30: 4 | K30: yes | L30: 10 | M30: They fitted me in the same day for an emergency and still finished the brake job on time. | N30: 4 | O30: 4 | P30: 4 | Q30: 4 | R30: 4 | S30: 4 | T30: =ROUND(AVERAGE(I30:J30),2) | U30: =ROUND(AVERAGE(N30:S30),2) | V30: =IF(L30>=9,"promoter",IF(L30>=7,"passive","detractor")) | W30: =IF(OR(V30="detractor",K30<>"yes"),1,0)
A31: 46208.419 | B31: Ibrahim Butt | C31: +971 50 000 0030 | D31: ibrahim.butt30@example.com | E31: Sharjah | F31: oil_change | G31: en | H31: link | I31: 5 | J31: 5 | K31: yes | L31: 10 | M31: WhatsApp updates through the day meant I never had to call and ask. | N31: 5 | O31: 5 | P31: 5 | Q31: 5 | R31: 4 | S31: 5 | T31: =ROUND(AVERAGE(I31:J31),2) | U31: =ROUND(AVERAGE(N31:S31),2) | V31: =IF(L31>=9,"promoter",IF(L31>=7,"passive","detractor")) | W31: =IF(OR(V31="detractor",K31<>"yes"),1,0)
A32: 46208.42 | B32: Deepak Malik | C32: +971 58 000 0031 | D32: deepak.malik31@example.com | E32: Al Ain | F32: oil_change | G32: en | H32: link | I32: 3 | J32: 4 | K32: yes | L32: 7 | M32: The car is running well. The advisor was hard to reach on the phone during the day. | N32: 5 | O32: 4 | P32: 5 | Q32: 4 | R32: 4 | S32: 3 | T32: =ROUND(AVERAGE(I32:J32),2) | U32: =ROUND(AVERAGE(N32:S32),2) | V32: =IF(L32>=9,"promoter",IF(L32>=7,"passive","detractor")) | W32: =IF(OR(V32="detractor",K32<>"yes"),1,0)
A33: 46208.527 | B33: Layla Joseph | C33: +971 54 000 0032 | D33: layla.joseph32@example.com | E33: Abu Dhabi | F33: electrical | G33: en | H33: portal | I33: 4 | J33: 4 | K33: partially | L33: 8 | M33: The repair is good. I only wish they had cleaned the interior after the electrical fault. | N33: 3 | O33: 4 | P33: 5 | Q33: 5 | R33: 3 | S33: 4 | T33: =ROUND(AVERAGE(I33:J33),2) | U33: =ROUND(AVERAGE(N33:S33),2) | V33: =IF(L33>=9,"promoter",IF(L33>=7,"passive","detractor")) | W33: =IF(OR(V33="detractor",K33<>"yes"),1,0) | X33: 46211.361 | Y33: Customer confirmed the repeat fault was fixed on the return visit and is satisfied now.
A34: 46208.601 | B34: Khalid Mendoza | C34: +971 54 000 0033 | D34: khalid.mendoza33@example.com | E34: Sharjah | F34: brake_repair | G34: en | H34: portal | I34: 5 | J34: 5 | K34: yes | L34: 10 | M34: The advisor remembered my car's history and flagged something due next service. Genuinely helpful. | N34: 5 | O34: 5 | P34: 5 | Q34: 5 | R34: 5 | S34: 5 | T34: =ROUND(AVERAGE(I34:J34),2) | U34: =ROUND(AVERAGE(N34:S34),2) | V34: =IF(L34>=9,"promoter",IF(L34>=7,"passive","detractor")) | W34: =IF(OR(V34="detractor",K34<>"yes"),1,0)
A35: 46208.687 | B35: Bilal Malik | C35: +971 56 000 0034 | D35: bilal.malik34@example.com | E35: Abu Dhabi | F35: brake_repair | G35: en | H35: link | I35: 5 | J35: 4 | K35: yes | L35: 9 | M35: Honest team — they told me one part I expected to replace was still fine. | N35: 5 | O35: 4 | P35: 4 | Q35: 5 | R35: 5 | S35: 5 | T35: =ROUND(AVERAGE(I35:J35),2) | U35: =ROUND(AVERAGE(N35:S35),2) | V35: =IF(L35>=9,"promoter",IF(L35>=7,"passive","detractor")) | W35: =IF(OR(V35="detractor",K35<>"yes"),1,0)
A36: 46208.866 | B36: Arun Al Kaabi | C36: +971 50 000 0035 | D36: arun.al.kaabi35@example.com | E36: Dubai | F36: diagnostic | G36: en | H36: link | I36: 5 | J36: 4 | K36: yes | L36: 10 | M36: Booked in the morning and picked the car up the same evening — the diagnostic check was done properly and the price matched the quote. | N36: 5 | O36: 5 | P36: 5 | Q36: 5 | R36: 5 | S36: 5 | T36: =ROUND(AVERAGE(I36:J36),2) | U36: =ROUND(AVERAGE(N36:S36),2) | V36: =IF(L36>=9,"promoter",IF(L36>=7,"passive","detractor")) | W36: =IF(OR(V36="detractor",K36<>"yes"),1,0)
A37: 46209.391 | B37: George Butt | C37: +971 50 000 0036 | D37: george.butt36@example.com | E37: Abu Dhabi | F37: bodywork | G37: en | H37: link | I37: 4 | J37: 4 | K37: yes | L37: 7 | M37: Quality is there. The appointment I booked still meant a 40-minute wait. | N37: 3 | O37: 4 | P37: 3 | Q37: 3 | R37: 2 | S37: 2 | T37: =ROUND(AVERAGE(I37:J37),2) | U37: =ROUND(AVERAGE(N37:S37),2) | V37: =IF(L37>=9,"promoter",IF(L37>=7,"passive","detractor")) | W37: =IF(OR(V37="detractor",K37<>"yes"),1,0)
A38: 46209.491 | B38: Naeem Al Hammadi | C38: +971 56 000 0037 | D38: naeem.al.hammadi37@example.com | E38: Sharjah | F38: bodywork | G38: en | H38: portal | I38: 5 | J38: 4 | K38: yes | L38: 10 | M38: Fair pricing compared to the agency, and the quality of the body repair was just as good. | N38: 4 | O38: 4 | P38: 5 | Q38: 5 | R38: 5 | S38: 5 | T38: =ROUND(AVERAGE(I38:J38),2) | U38: =ROUND(AVERAGE(N38:S38),2) | V38: =IF(L38>=9,"promoter",IF(L38>=7,"passive","detractor")) | W38: =IF(OR(V38="detractor",K38<>"yes"),1,0)
A39: 46209.518 | B39: Manoj Al Yammahi | C39: +971 50 000 0038 | D39: manoj.al.yammahi38@example.com | E39: Abu Dhabi | F39: tire_service | G39: en | H39: link | I39: 4 | J39: 4 | K39: yes | L39: 7 | M39: Overall okay. Slightly expensive for what was done, but the work looks sound. | N39: 4 | O39: 4 | P39: 4 | Q39: 4 | R39: 4 | S39: 3 | T39: =ROUND(AVERAGE(I39:J39),2) | U39: =ROUND(AVERAGE(N39:S39),2) | V39: =IF(L39>=9,"promoter",IF(L39>=7,"passive","detractor")) | W39: =IF(OR(V39="detractor",K39<>"yes"),1,0)
A40: 46209.615 | B40: Paul Al Rashidi | C40: +971 54 000 0039 | D40: paul.al.rashidi39@example.com | E40: Abu Dhabi | F40: tire_service | G40: en | H40: link | I40: 5 | J40: 5 | K40: yes | L40: 10 | M40: Quick, clean and reasonably priced. the tyre work was exactly what I asked for. | N40: 5 | O40: 4 | P40: 5 | Q40: 5 | R40: 5 | S40: 5 | T40: =ROUND(AVERAGE(I40:J40),2) | U40: =ROUND(AVERAGE(N40:S40),2) | V40: =IF(L40>=9,"promoter",IF(L40>=7,"passive","detractor")) | W40: =IF(OR(V40="detractor",K40<>"yes"),1,0)
...

Sheet Monthly Summary
A1: Pioneer Car Service Center — Customer Experience, July 2026
A2: Synthetic dataset. See the Notes sheet before using these figures anywhere.
A4: Headline measures
A5: Responses received | B5: =COUNTA(Responses!$B$2:$B$165)
A6: Net Promoter Score | B6: =ROUND((COUNTIF(Responses!$V$2:$V$165,"promoter")-COUNTIF(Responses!$V$2:$V$165,"detractor"))/COUNTA(Responses!$V$2:$V$165)*100,0)
A7: Customer satisfaction (mean of 5) | B7: =ROUND(AVERAGE(Responses!$U$2:$U$165),2)
A8: Customer Effort Score (mean of 5) | B8: =ROUND(AVERAGE(Responses!$T$2:$T$165),2)
A9: Mean recommendation score (of 10) | B9: =ROUND(AVERAGE(Responses!$L$2:$L$165),2)
A10: Fully resolved | B10: =ROUND(COUNTIF(Responses!$K$2:$K$165,"yes")/COUNTA(Responses!$K$2:$K$165)*100,1)
A11: Flagged for follow-up | B11: =SUM(Responses!$W$2:$W$165)
A12: Follow-up completed | B12: =COUNT(Responses!$X$2:$X$165)
A13: Follow-up still outstanding | B13: =B11-B12
A15: NPS breakdown | C15: Share
A16: Promoters | B16: =COUNTIF(Responses!$V$2:$V$165,"promoter") | C16: =ROUND(B16/$B$5*100,1)
A17: Passives | B17: =COUNTIF(Responses!$V$2:$V$165,"passive") | C17: =ROUND(B17/$B$5*100,1)
A18: Detractors | B18: =COUNTIF(Responses!$V$2:$V$165,"detractor") | C18: =ROUND(B18/$B$5*100,1)
A20: By branch
A21: Branch | B21: Responses | C21: NPS | D21: CSAT | E21: CES
A22: Abu Dhabi | B22: =COUNTIF(Responses!$E$2:$E$165,$A22) | C22: =IF(B22=0,"",ROUND((COUNTIFS(Responses!$E$2:$E$165,$A22,Responses!$V$2:$V$165,"promoter")-COUNTIFS(Responses!$E$2:$E$165,$A22,Responses!$V$2:$V$165,"detractor"))/B22*100,0)) | D22: =IF(B22=0,"",ROUND(AVERAGEIF(Responses!$E$2:$E$165,$A22,Responses!$U$2:$U$165),2)) | E22: =IF(B22=0,"",ROUND(AVERAGEIF(Responses!$E$2:$E$165,$A22,Responses!$T$2:$T$165),2))
A23: Sharjah | B23: =COUNTIF(Responses!$E$2:$E$165,$A23) | C23: =IF(B23=0,"",ROUND((COUNTIFS(Responses!$E$2:$E$165,$A23,Responses!$V$2:$V$165,"promoter")-COUNTIFS(Responses!$E$2:$E$165,$A23,Responses!$V$2:$V$165,"detractor"))/B23*100,0)) | D23: =IF(B23=0,"",ROUND(AVERAGEIF(Responses!$E$2:$E$165,$A23,Responses!$U$2:$U$165),2)) | E23: =IF(B23=0,"",ROUND(AVERAGEIF(Responses!$E$2:$E$165,$A23,Responses!$T$2:$T$165),2))
A24: Dubai | B24: =COUNTIF(Responses!$E$2:$E$165,$A24) | C24: =IF(B24=0,"",ROUND((COUNTIFS(Responses!$E$2:$E$165,$A24,Responses!$V$2:$V$165,"promoter")-COUNTIFS(Responses!$E$2:$E$165,$A24,Responses!$V$2:$V$165,"detractor"))/B24*100,0)) | D24: =IF(B24=0,"",ROUND(AVERAGEIF(Responses!$E$2:$E$165,$A24,Responses!$U$2:$U$165),2)) | E24: =IF(B24=0,"",ROUND(AVERAGEIF(Responses!$E$2:$E$165,$A24,Responses!$T$2:$T$165),2))
A25: Al Ain | B25: =COUNTIF(Responses!$E$2:$E$165,$A25) | C25: =IF(B25=0,"",ROUND((COUNTIFS(Responses!$E$2:$E$165,$A25,Responses!$V$2:$V$165,"promoter")-COUNTIFS(Responses!$E$2:$E$165,$A25,Responses!$V$2:$V$165,"detractor"))/B25*100,0)) | D25: =IF(B25=0,"",ROUND(AVERAGEIF(Responses!$E$2:$E$165,$A25,Responses!$U$2:$U$165),2)) | E25: =IF(B25=0,"",ROUND(AVERAGEIF(Responses!$E$2:$E$165,$A25,Responses!$T$2:$T$165),2))
A27: By service
A28: Service | B28: Responses | C28: NPS | D28: CSAT
A29: oil_change | B29: =COUNTIF(Responses!$F$2:$F$165,$A29) | C29: =IF(B29=0,"",ROUND((COUNTIFS(Responses!$F$2:$F$165,$A29,Responses!$V$2:$V$165,"promoter")-COUNTIFS(Responses!$F$2:$F$165,$A29,Responses!$V$2:$V$165,"detractor"))/B29*100,0)) | D29: =IF(B29=0,"",ROUND(AVERAGEIF(Responses!$F$2:$F$165,$A29,Responses!$U$2:$U$165),2))
A30: general_maintenance | B30: =COUNTIF(Responses!$F$2:$F$165,$A30) | C30: =IF(B30=0,"",ROUND((COUNTIFS(Responses!$F$2:$F$165,$A30,Responses!$V$2:$V$165,"promoter")-COUNTIFS(Responses!$F$2:$F$165,$A30,Responses!$V$2:$V$165,"detractor"))/B30*100,0)) | D30: =IF(B30=0,"",ROUND(AVERAGEIF(Responses!$F$2:$F$165,$A30,Responses!$U$2:$U$165),2))
A31: tire_service | B31: =COUNTIF(Responses!$F$2:$F$165,$A31) | C31: =IF(B31=0,"",ROUND((COUNTIFS(Responses!$F$2:$F$165,$A31,Responses!$V$2:$V$165,"promoter")-COUNTIFS(Responses!$F$2:$F$165,$A31,Responses!$V$2:$V$165,"detractor"))/B31*100,0)) | D31: =IF(B31=0,"",ROUND(AVERAGEIF(Responses!$F$2:$F$165,$A31,Responses!$U$2:$U$165),2))
A32: brake_repair | B32: =COUNTIF(Responses!$F$2:$F$165,$A32) | C32: =IF(B32=0,"",ROUND((COUNTIFS(Responses!$F$2:$F$165,$A32,Responses!$V$2:$V$165,"promoter")-COUNTIFS(Responses!$F$2:$F$165,$A32,Responses!$V$2:$V$165,"detractor"))/B32*100,0)) | D32: =IF(B32=0,"",ROUND(AVERAGEIF(Responses!$F$2:$F$165,$A32,Responses!$U$2:$U$165),2))
A33: engine_repair | B33: =COUNTIF(Responses!$F$2:$F$165,$A33) | C33: =IF(B33=0,"",ROUND((COUNTIFS(Responses!$F$2:$F$165,$A33,Responses!$V$2:$V$165,"promoter")-COUNTIFS(Responses!$F$2:$F$165,$A33,Responses!$V$2:$V$165,"detractor"))/B33*100,0)) | D33: =IF(B33=0,"",ROUND(AVERAGEIF(Responses!$F$2:$F$165,$A33,Responses!$U$2:$U$165),2))
A34: electrical | B34: =COUNTIF(Responses!$F$2:$F$165,$A34) | C34: =IF(B34=0,"",ROUND((COUNTIFS(Responses!$F$2:$F$165,$A34,Responses!$V$2:$V$165,"promoter")-COUNTIFS(Responses!$F$2:$F$165,$A34,Responses!$V$2:$V$165,"detractor"))/B34*100,0)) | D34: =IF(B34=0,"",ROUND(AVERAGEIF(Responses!$F$2:$F$165,$A34,Responses!$U$2:$U$165),2))
A35: bodywork | B35: =COUNTIF(Responses!$F$2:$F$165,$A35) | C35: =IF(B35=0,"",ROUND((COUNTIFS(Responses!$F$2:$F$165,$A35,Responses!$V$2:$V$165,"promoter")-COUNTIFS(Responses!$F$2:$F$165,$A35,Responses!$V$2:$V$165,"detractor"))/B35*100,0)) | D35: =IF(B35=0,"",ROUND(AVERAGEIF(Responses!$F$2:$F$165,$A35,Responses!$U$2:$U$165),2))
A36: diagnostic | B36: =COUNTIF(Responses!$F$2:$F$165,$A36) | C36: =IF(B36=0,"",ROUND((COUNTIFS(Responses!$F$2:$F$165,$A36,Responses!$V$2:$V$165,"promoter")-COUNTIFS(Responses!$F$2:$F$165,$A36,Responses!$V$2:$V$165,"detractor"))/B36*100,0)) | D36: =IF(B36=0,"",ROUND(AVERAGEIF(Responses!$F$2:$F$165,$A36,Responses!$U$2:$U$165),2))
A37: transmission | B37: =COUNTIF(Responses!$F$2:$F$165,$A37) | C37: =IF(B37=0,"",ROUND((COUNTIFS(Responses!$F$2:$F$165,$A37,Responses!$V$2:$V$165,"promoter")-COUNTIFS(Responses!$F$2:$F$165,$A37,Responses!$V$2:$V$165,"detractor"))/B37*100,0)) | D37: =IF(B37=0,"",ROUND(AVERAGEIF(Responses!$F$2:$F$165,$A37,Responses!$U$2:$U$165),2))
A38: other | B38: =COUNTIF(Responses!$F$2:$F$165,$A38) | C38: =IF(B38=0,"",ROUND((COUNTIFS(Responses!$F$2:$F$165,$A38,Responses!$V$2:$V$165,"promoter")-COUNTIFS(Responses!$F$2:$F$165,$A38,Responses!$V$2:$V$165,"detractor"))/B38*100,0)) | D38: =IF(B38=0,"",ROUND(AVERAGEIF(Responses!$F$2:$F$165,$A38,Responses!$U$2:$U$165),2))
A40: Formulas read the Responses sheet directly — change a row there and every figure above updates when the workbook recalculates.

Sheet Notes
A1: Pioneer Car Service Center — CX survey dataset, July 2026
A3: What this is
A4: 164 customer survey responses covering 1–31 July 2026, in the exact column shape of the survey_responses table. Every row has a respondent name, a branch and a service, which is what the Customer Experience dashboard needs in order to show per-branch and per-service breakdowns.
A6: These respondents are not real customers
A7: The names, scores and comments were generated for demonstration and testing. They are not the words of any Pioneer customer and must not be reported as voice-of-customer evidence, quoted in a management pack, or mixed into a real CX report without saying where they came from.
A9: Contact details cannot reach anyone, by design
A10: Phone numbers use the +971 5x 000 0xxx block, which is not an assigned UAE subscriber range, so no number here can connect to a real person. Emails use example.com, reserved by RFC 2606 and permanently undeliverable. This matters because the CX workflow asks staff to call flagged detractors back — with real-looking numbers, a demo would eventually dial a stranger.
A12: How the numbers were shaped
A13: Roughly 57% promoters, 27% passives and 16% detractors, giving an NPS near +41. CSAT and CES answers are drawn to agree with each row's NPS band, so a promoter does not score 2s. Dates are weekday-weighted for the UAE working week (Friday lightest) and fall in workshop hours. Detractors and any response that was not fully resolved are flagged, and about 78% of those carry a completed follow-up with a recorded outcome.
A15: Loading it
A16: node scripts/import-survey-responses.js --file=<this file> --dry-run
A17: Drop --dry-run to write. The importer recomputes ces_avg, csat_avg, nps_category and is_flagged from the answer columns rather than trusting the sheet, and stamps user_agent with a seed marker.
... A24: Generated with a fixed random seed (20260701), so regenerating produces this same sheet rather than a different one.
