Workbook

Sheet Complaints
A1: Case no. | B1: Logged | C1: Sev | D1: Repeat | E1: Status | F1: Channel | G1: Customer | H1: Work order | I1: Amount (AED) | J1: Complaint | K1: Acknowledged | L1: Target | M1: Resolved | N1: Ack (hrs) | O1: Resolve (days) | P1: Within target | Q1: Outcome | R1: Outcome told | S1: Resolution | T1: Root cause type | U1: Root cause | V1: Corrective action | W1: CA due | X1: CA closed | Y1: Cust. confirmed | Z1: Escalated | AA1: Authority | AB1: Owner
A2: CMP-20251013-9520 | B2: 45943.594 | C2: S1 | E2: resolved | F2: in_person | G2: HUMA ASIM HASSAN KORRANI | I2: 0 | J2: New brake pads are squealing already, worse than before the service. | K2: 45943.803 | L2: 45945.594 | M2: 45944.92 | N2: =IF(K2="","",ROUND((K2-B2)*24,1)) | O2: =IF(M2="","",ROUND(M2-B2,1)) | P2: =IF(M2="","",IF(M2<=L2,"yes","no")) | Q2: goodwill | R2: 45945.212 | S2: No billing error found, but offered a complimentary detail as a goodwill gesture for the inconvenience. | T2: machine | U2: A bay lift service interval was missed, which delayed the job by a day. | V2: Added a parts-match check against the job card before issue from stores. | W2: 45967 | Y2: 45945.878 | AA2: manager | AB2: Priya Menon
A3: CMP-20251123-7514 | B3: 45984.5 | C3: S2 | E3: resolved | F3: whatsapp | G3: AMAN TAXI - SOLE PROPRIETORSHIP L.L.C.(AUH/AA) | I3: 0 | J3: Vehicle was ready two days later than promised, with no update until I called in myself. | K3: 45985.084 | L3: 45990.5 | M3: 45989.625 | N3: =IF(K3="","",ROUND((K3-B3)*24,1)) | O3: =IF(M3="","",ROUND(M3-B3,1)) | P3: =IF(M3="","",IF(M3<=L3,"yes","no")) | Q3: partial_refund | R3: 45990.291 | S3: Split the difference: goodwill refund for the delay, full charge retained for the work performed. | Y3: 45990.5 | AA3: manager | AB3: Tarek El Sayed
A4: CMP-20251207-2716 | B4: 45998.407 | C4: S2 | E4: resolved | F4: in_person | G4: Abdallah Bsileh | I4: 85 | J4: Invoice included a diagnostic fee I was told would be waived since I went ahead with the repair. | K4: 45999.115 | L4: 46004.407 | M4: 46004.907 | N4: =IF(K4="","",ROUND((K4-B4)*24,1)) | O4: =IF(M4="","",ROUND(M4-B4,1)) | P4: =IF(M4="","",IF(M4<=L4,"yes","no")) | Q4: goodwill | R4: 46004.907 | S4: No billing error found, but offered a complimentary detail as a goodwill gesture for the inconvenience. | AA4: manager | AB4: Priya Menon
A5: CMP-20251209-5216 | B5: 46000.532 | C5: S2 | E5: resolved | F5: email | G5: PRUDHVI TEJ VUNDRU | I5: 0 | J5: Paint touch-up doesn't match the original colour on the panel. | K5: 46001.115 | L5: 46006.532 | M5: 46004.789 | N5: =IF(K5="","",ROUND((K5-B5)*24,1)) | O5: =IF(M5="","",ROUND(M5-B5,1)) | P5: =IF(M5="","",IF(M5<=L5,"yes","no")) | Q5: charge_correct | R5: 46005.247 | S5: Estimate covered parts only per the original quote; the labour line was itemised separately from the start. No adjustment due. | AA5: manager | AB5: Workshop Manager
A6: CMP-20260113-8855 | B6: 46035.594 | C6: S2 | E6: closed | F6: in_person | G6: SAEED OMEIR YOUSEF AHMED ALMH | I6: 0 | J6: AC still isn't cooling properly after paying for the recharge service. | K6: 46035.844 | L6: 46041.594 | M6: 46039.299 | N6: =IF(K6="","",ROUND((K6-B6)*24,1)) | O6: =IF(M6="","",ROUND(M6-B6,1)) | P6: =IF(M6="","",IF(M6<=L6,"yes","no")) | Q6: refund_due | R6: 46039.715 | S6: Reviewed the job card against the original estimate — the extra charge was not pre-approved, so a refund was issued for the difference. | Y6: 46041.299 | AA6: manager | AB6: Tarek El Sayed
A7: CMP-20260124-6300 | B7: 46046.365 | C7: S2 | E7: closed | F7: in_person | G7: FAISAL KUNHABDULLA KUNHABDULLA | I7: 0 | J7: The service reminder light was never reset after the oil change. | K7: 46046.448 | L7: 46051.365 | M7: 46053.406 | N7: =IF(K7="","",ROUND((K7-B7)*24,1)) | O7: =IF(M7="","",ROUND(M7-B7,1)) | P7: =IF(M7="","",IF(M7<=L7,"yes","no")) | Q7: goodwill | R7: 46054.073 | S7: No billing error found, but offered a complimentary detail as a goodwill gesture for the inconvenience. | Y7: 46055.156 | AA7: manager | AB7: Workshop Manager
A8: CMP-20260209-5728 | B8: 46062.75 | C8: S2 | E8: closed | F8: phone | G8: FAHAD MOHAMAD SHAHDAD ALBLOUSHI | I8: 133 | J8: Invoice included a diagnostic fee I was told would be waived since I went ahead with the repair. | K8: 46062.917 | L8: 46068.75 | M8: 46068.203 | N8: =IF(K8="","",ROUND((K8-B8)*24,1)) | O8: =IF(M8="","",ROUND(M8-B8,1)) | P8: =IF(M8="","",IF(M8<=L8,"yes","no")) | Q8: charge_correct | R8: 46068.536 | S8: Walked the customer through the job card and photos taken during the work — the additional labour matched what was actually required. Charge stands, explained clearly. | Y8: 46070.161 | AA8: manager | AB8: Workshop Manager
A9: CMP-20260216-7892 | B9: 46069.479 | C9: S2 | E9: closed | F9: in_person | G9: MR-AHMED DAKHLAOUI | I9: 1148 | J9: Wasn't told the warranty wouldn't cover the part that was replaced, only found out on the invoice. | K9: 46069.813 | L9: 46075.479 | M9: 46074.392 | N9: =IF(K9="","",ROUND((K9-B9)*24,1)) | O9: =IF(M9="","",ROUND(M9-B9,1)) | P9: =IF(M9="","",IF(M9<=L9,"yes","no")) | Q9: refund_due | R9: 46075.392 | S9: Reviewed the job card against the original estimate — the extra charge was not pre-approved, so a refund was issued for the difference. | Y9: 46075.433 | AA9: manager | AB9: Nadia Khoury
A10: CMP-20260228-9281 | B10: 46081.677 | C10: S2 | E10: resolved | F10: whatsapp | G10: ABDULAZIZ SULTAN OBAID | I10: 629 | J10: Was quoted one price over the phone and charged a higher one at pickup. | K10: 46081.927 | L10: 46086.677 | M10: 46084.601 | N10: =IF(K10="","",ROUND((K10-B10)*24,1)) | O10: =IF(M10="","",ROUND(M10-B10,1)) | P10: =IF(M10="","",IF(M10<=L10,"yes","no")) | Q10: goodwill | R10: 46085.517 | S10: Free re-check booked at no charge and a discount applied to the next visit as a gesture of goodwill. | T10: machine | U10: A bay lift service interval was missed, which delayed the job by a day. | V10: Callback checklist step made mandatory regardless of workload, with a supervisor spot-check. | W10: 46100 | AA10: manager | AB10: Nadia Khoury
A11: CMP-20260307-6577 | B11: 46088.375 | C11: S2 | E11: resolved | F11: email | G11: MR-MUBARAKA MOHAMED AHMED ALME | I11: 0 | J11: The wrong part was fitted — had to bring the car back a second time for the same job. | K11: 46089.625 | L11: 46093.375 | M11: 46091.7 | N11: =IF(K11="","",ROUND((K11-B11)*24,1)) | O11: =IF(M11="","",ROUND(M11-B11,1)) | P11: =IF(M11="","",IF(M11<=L11,"yes","no")) | Q11: goodwill | R11: 46092.491 | S11: Free re-check booked at no charge and a discount applied to the next visit as a gesture of goodwill. | Y11: 46093.908 | AA11: manager | AB11: Workshop Manager
A12: CMP-20260317-2464 | B12: 46098.365 | C12: S2 | E12: resolved | F12: phone | G12: PRIYANKA JEGANATHAN BHARAT KUMAR | I12: 0 | J12: The wrong part was fitted — had to bring the car back a second time for the same job. | K12: 46098.532 | L12: 46104.365 | M12: 46102.922 | N12: =IF(K12="","",ROUND((K12-B12)*24,1)) | O12: =IF(M12="","",ROUND(M12-B12,1)) | P12: =IF(M12="","",IF(M12<=L12,"yes","no")) | Q12: goodwill | R12: 46103.38 | S12: Free re-check booked at no charge and a discount applied to the next visit as a gesture of goodwill. | Y12: 46104.463 | AA12: manager | AB12: Workshop Manager
A13: CMP-20260322-2157 | B13: 46103.802 | C13: S3 | E13: closed | F13: phone | G13: DINESH MALLIA LAKSHMANA MALLIA | I13: 0 | J13: Left a voicemail for a status update four days ago, still no callback. | K13: 46104.594 | L13: 46106.802 | M13: 46106.357 | N13: =IF(K13="","",ROUND((K13-B13)*24,1)) | O13: =IF(M13="","",ROUND(M13-B13,1)) | P13: =IF(M13="","",IF(M13<=L13,"yes","no")) | Q13: partial_refund | R13: 46106.649 | S13: Split the difference: goodwill refund for the delay, full charge retained for the work performed. | Y13: 46108.565 | AA13: advisor | AB13: Tarek El Sayed
A14: CMP-20260326-7184 | B14: 46107.792 | C14: S2 | E14: resolved | F14: phone | G14: ARCHANA SURESH BABU | I14: 0 | J14: Car came back with a scratch on the bumper that wasn't there at drop-off. | K14: 46109.75 | L14: 46113.792 | M14: 46113.685 | N14: =IF(K14="","",ROUND((K14-B14)*24,1)) | O14: =IF(M14="","",ROUND(M14-B14,1)) | P14: =IF(M14="","",IF(M14<=L14,"yes","no")) | Q14: refund_due | R14: 46113.935 | S14: Confirmed the part billed was not the one fitted. Refunded the line item. | AA14: manager | AB14: Nadia Khoury
A15: CMP-20260401-7012 | B15: 46113.553 | C15: S1 | E15: investigating | F15: phone | G15: PETER NIGEL SOOSAI MECHAEL | I15: 0 | J15: The same noise came back within a week of the repair it was supposedly fixed for. | K15: 46114.094 | L15: 46116.553 | N15: =IF(K15="","",ROUND((K15-B15)*24,1)) | O15: =IF(M15="","",ROUND(M15-B15,1)) | P15: =IF(M15="","",IF(M15<=L15,"yes","no")) | Q15: pending | Z15: 46118.469 | AA15: senior | AB15: Tarek El Sayed
A16: CMP-20260402-5537 | B16: 46114.396 | C16: S2 | E16: closed | F16: email | G16: RATHEESH POILINGAL KRISHNANKUTTY | I16: 811 | J16: Wasn't told the warranty wouldn't cover the part that was replaced, only found out on the invoice. | K16: 46114.521 | L16: 46120.396 | M16: 46118.434 | N16: =IF(K16="","",ROUND((K16-B16)*24,1)) | O16: =IF(M16="","",ROUND(M16-B16,1)) | P16: =IF(M16="","",IF(M16<=L16,"yes","no")) | Q16: charge_correct | R16: 46118.85 | S16: Walked the customer through the job card and photos taken during the work — the additional labour matched what was actually required. Charge stands, explained clearly. | Y16: 46119.725 | AA16: manager | AB16: Workshop Manager
A17: CMP-20260402-8174 | B17: 46114.792 | C17: S2 | E17: resolved | F17: phone | G17: ABHAI ASOKAN ASOKAN DIVAKARAN | I17: 0 | J17: The service reminder light was never reset after the oil change. | K17: 46115.542 | L17: 46120.792 | M17: 46120.588 | N17: =IF(K17="","",ROUND((K17-B17)*24,1)) | O17: =IF(M17="","",ROUND(M17-B17,1)) | P17: =IF(M17="","",IF(M17<=L17,"yes","no")) | Q17: refund_due | S17: Reviewed the job card against the original estimate — the extra charge was not pre-approved, so a refund was issued for the difference. | T17: machine | U17: A bay lift service interval was missed, which delayed the job by a day. | V17: Briefing added to the technician handover sheet for repeat-fault vehicles. | W17: 46150 | AA17: manager | AB17: Workshop Manager
A18: CMP-20260407-2068 | B18: 46119.698 | C18: S2 | E18: closed | F18: in_person | G18: NAILA OBAID MOHAMMAD ABAID AL SUWAIDI | I18: 0 | J18: Paint touch-up doesn't match the original colour on the panel. | K18: 46120.198 | L18: 46125.698 | M18: 46123.624 | N18: =IF(K18="","",ROUND((K18-B18)*24,1)) | O18: =IF(M18="","",ROUND(M18-B18,1)) | P18: =IF(M18="","",IF(M18<=L18,"yes","no")) | Q18: partial_refund | R18: 46124.04 | S18: Partial refund agreed — the diagnostic fee should have been waived per policy, the labour charge itself was correct. | Y18: 46124.707 | AA18: manager | AB18: Priya Menon
A19: CMP-20260411-5373 | B19: 46123.469 | C19: S2 | E19: resolved | F19: whatsapp | G19: HAJRA BASHEER | I19: 781 | J19: Was quoted one price over the phone and charged a higher one at pickup. | K19: 46124.136 | L19: 46128.469 | M19: 46131.177 | N19: =IF(K19="","",ROUND((K19-B19)*24,1)) | O19: =IF(M19="","",ROUND(M19-B19,1)) | P19: =IF(M19="","",IF(M19<=L19,"yes","no")) | Q19: refund_due | S19: Reviewed the job card against the original estimate — the extra charge was not pre-approved, so a refund was issued for the difference. | AA19: manager | AB19: Nadia Khoury
A20: CMP-20260507-6754 | B20: 46149.365 | C20: S3 | E20: resolved | F20: phone | G20: RIYAS VELLAMCHOLA AVARAN AVARAN | I20: 0 | J20: Left a voicemail for a status update four days ago, still no callback. | K20: 46149.657 | L20: 46153.365 | M20: 46153.288 | N20: =IF(K20="","",ROUND((K20-B20)*24,1)) | O20: =IF(M20="","",ROUND(M20-B20,1)) | P20: =IF(M20="","",IF(M20<=L20,"yes","no")) | Q20: charge_correct | R20: 46153.372 | S20: Estimate covered parts only per the original quote; the labour line was itemised separately from the start. No adjustment due. | Y20: 46155.33 | AA20: advisor | AB20: Nadia Khoury
A21: CMP-20260509-6846 | B21: 46151.469 | C21: S2 | E21: closed | F21: portal | G21: DHANRAJ SALIAN SHEKAR | I21: 90 | J21: Invoice included a diagnostic fee I was told would be waived since I went ahead with the repair. | K21: 46152.011 | L21: 46156.469 | M21: 46155.181 | N21: =IF(K21="","",ROUND((K21-B21)*24,1)) | O21: =IF(M21="","",ROUND(M21-B21,1)) | P21: =IF(M21="","",IF(M21<=L21,"yes","no")) | Q21: goodwill | R21: 46155.806 | S21: Free re-check booked at no charge and a discount applied to the next visit as a gesture of goodwill. | T21: method | U21: Job-card sign-off procedure did not require a supervisor check before closing out the line. | V21: Added a parts-match check against the job card before issue from stores. | W21: 46172 | Y21: 46156.973 | AA21: manager | AB21: Priya Menon
A22: CMP-20260509-1147 | B22: 46151.782 | C22: S2 | E22: closed | F22: phone | G22: MUHAMMAD ASIM JAVED | I22: 953 | J22: Was quoted one price over the phone and charged a higher one at pickup. | K22: 46152.573 | L22: 46156.782 | M22: 46155.517 | N22: =IF(K22="","",ROUND((K22-B22)*24,1)) | O22: =IF(M22="","",ROUND(M22-B22,1)) | P22: =IF(M22="","",IF(M22<=L22,"yes","no")) | Q22: partial_refund | R22: 46156.059 | S22: Split the difference: goodwill refund for the delay, full charge retained for the work performed. | Y22: 46157.684 | AA22: manager | AB22: Workshop Manager
A23: CMP-20260515-1939 | B23: 46157.709 | C23: S3 | E23: resolved | F23: in_person | G23: MR-MUDASSAR HUDAIN LAL KHAN | I23: 0 | J23: Left a voicemail for a status update four days ago, still no callback. | K23: 46158.417 | L23: 46160.709 | M23: 46159.645 | N23: =IF(K23="","",ROUND((K23-B23)*24,1)) | O23: =IF(M23="","",ROUND(M23-B23,1)) | P23: =IF(M23="","",IF(M23<=L23,"yes","no")) | Q23: charge_correct | R23: 46160.02 | S23: Estimate covered parts only per the original quote; the labour line was itemised separately from the start. No adjustment due. | Y23: 46160.77 | AA23: advisor | AB23: Tarek El Sayed
A24: CMP-20260519-1775 | B24: 46161.365 | C24: S1 | D24: yes | E24: resolved | F24: in_person | G24: ARCHANA SURESH BABU | I24: 0 | J24: The wrong part was fitted — had to bring the car back a second time for the same job. | K24: 46162.198 | L24: 46163.365 | M24: 46162.772 | N24: =IF(K24="","",ROUND((K24-B24)*24,1)) | O24: =IF(M24="","",ROUND(M24-B24,1)) | P24: =IF(M24="","",IF(M24<=L24,"yes","no")) | Q24: charge_correct | S24: Walked the customer through the job card and photos taken during the work — the additional labour matched what was actually required. Charge stands, explained clearly. | T24: material | U24: The part received from the supplier did not match the OEM spec logged on the job card. | V24: Callback checklist step made mandatory regardless of workload, with a supervisor spot-check. | W24: 46191 | AA24: manager | AB24: Priya Menon
A25: CMP-20260524-2877 | B25: 46166.605 | C25: S3 | E25: resolved | F25: in_person | G25: Bassam Daher | I25: 0 | J25: Called three times about the delay and no one returned the call. | K25: 46168.063 | L25: 46169.605 | M25: 46169.064 | N25: =IF(K25="","",ROUND((K25-B25)*24,1)) | O25: =IF(M25="","",ROUND(M25-B25,1)) | P25: =IF(M25="","",IF(M25<=L25,"yes","no")) | Q25: charge_correct | R25: 46169.064 | S25: Walked the customer through the job card and photos taken during the work — the additional labour matched what was actually required. Charge stands, explained clearly. | T25: manpower | U25: The technician assigned had not been briefed on this vehicle's known fault history. | V25: Scheduled equipment recalibration and added it to the maintenance calendar. | W25: 46177 | AA25: advisor | AB25: Nadia Khoury
A26: CMP-20260601-8670 | B26: 46174.458 | C26: S3 | E26: resolved | F26: phone | G26: MR-MUNA MOHAMED SULTAN ALRIYAMI | I26: 0 | J26: Left a voicemail for a status update four days ago, still no callback. | K26: 46175.042 | L26: 46177.458 | M26: 46177.193 | N26: =IF(K26="","",ROUND((K26-B26)*24,1)) | O26: =IF(M26="","",ROUND(M26-B26,1)) | P26: =IF(M26="","",IF(M26<=L26,"yes","no")) | Q26: charge_correct | R26: 46177.985 | S26: Estimate covered parts only per the original quote; the labour line was itemised separately from the start. No adjustment due. | T26: material | U26: The wrong part was picked from stores against a similar part number. | V26: Briefing added to the technician handover sheet for repeat-fault vehicles. | W26: 46182 | Y26: 46178.818 | AA26: advisor | AB26: Tarek El Sayed
A27: CMP-20260603-7669 | B27: 46176.657 | C27: S2 | E27: resolved | F27: phone | G27: DHAFER MOHAMMED KANAN MOHAM | I27: 0 | J27: AC still isn't cooling properly after paying for the recharge service. | K27: 46177.198 | L27: 46182.657 | M27: 46180.178 | N27: =IF(K27="","",ROUND((K27-B27)*24,1)) | O27: =IF(M27="","",ROUND(M27-B27,1)) | P27: =IF(M27="","",IF(M27<=L27,"yes","no")) | Q27: goodwill | R27: 46180.553 | S27: No billing error found, but offered a complimentary detail as a goodwill gesture for the inconvenience. | Y27: 46181.22 | AA27: manager | AB27: Tarek El Sayed
A28: CMP-20260611-4767 | B28: 46184.417 | C28: S2 | E28: resolved | F28: phone | G28: ASHRAF MULAKUMTHOTTATHIL HUSS | I28: 450 | J28: Charged for more labour hours than the original estimate without being told beforehand. | K28: 46186.709 | L28: 46190.417 | M28: 46194.417 | N28: =IF(K28="","",ROUND((K28-B28)*24,1)) | O28: =IF(M28="","",ROUND(M28-B28,1)) | P28: =IF(M28="","",IF(M28<=L28,"yes","no")) | Q28: charge_correct | R28: 46194.959 | S28: Walked the customer through the job card and photos taken during the work — the additional labour matched what was actually required. Charge stands, explained clearly. | AA28: manager | AB28: Nadia Khoury
A29: CMP-20260612-5315 | B29: 46185.605 | C29: S1 | E29: resolved | F29: in_person | G29: Neha Rao | I29: 0 | J29: New brake pads are squealing already, worse than before the service. | K29: 46186.438 | L29: 46187.605 | M29: 46188.48 | N29: =IF(K29="","",ROUND((K29-B29)*24,1)) | O29: =IF(M29="","",ROUND(M29-B29,1)) | P29: =IF(M29="","",IF(M29<=L29,"yes","no")) | Q29: charge_correct | R29: 46189.23 | S29: Estimate covered parts only per the original quote; the labour line was itemised separately from the start. No adjustment due. | T29: machine | U29: A bay lift service interval was missed, which delayed the job by a day. | V29: QC road test now logged as a required field before a job can be marked ready for pickup. | W29: 46203 | Y29: 46189.855 | AA29: manager | AB29: Nadia Khoury
A30: CMP-20260618-3441 | B30: 46191.657 | C30: S1 | E30: resolved | F30: whatsapp | G30: AHMAD HUSNI MOHD ABED KHATER | I30: 0 | J30: The same noise came back within a week of the repair it was supposedly fixed for. | K30: 46192.448 | L30: 46194.657 | M30: 46193.865 | N30: =IF(K30="","",ROUND((K30-B30)*24,1)) | O30: =IF(M30="","",ROUND(M30-B30,1)) | P30: =IF(M30="","",IF(M30<=L30,"yes","no")) | Q30: refund_due | R30: 46194.615 | S30: Reviewed the job card against the original estimate — the extra charge was not pre-approved, so a refund was issued for the difference. | T30: manpower | U30: The advisor covering the desk that day had not been trained on the price-change approval step. | V30: Callback checklist step made mandatory regardless of workload, with a supervisor spot-check. | W30: 46198 | Y30: 46195.865 | AA30: manager | AB30: Priya Menon
A31: CMP-20260619-2002 | B31: 46192.75 | C31: S3 | E31: resolved | F31: phone | G31: MR-PHINOJ GEORGE VALLAPPADY GEORGE | I31: 0 | J31: Left a voicemail for a status update four days ago, still no callback. | K31: 46192.792 | L31: 46195.75 | M31: 46194.412 | N31: =IF(K31="","",ROUND((K31-B31)*24,1)) | O31: =IF(M31="","",ROUND(M31-B31,1)) | P31: =IF(M31="","",IF(M31<=L31,"yes","no")) | Q31: refund_due | R31: 46194.746 | S31: Confirmed the part billed was not the one fitted. Refunded the line item. | T31: material | U31: The part received from the supplier did not match the OEM spec logged on the job card. | V31: QC road test now logged as a required field before a job can be marked ready for pickup. | W31: 46212 | Y31: 46195.537 | AA31: advisor | AB31: Tarek El Sayed
A32: CMP-20260630-2493 | B32: 46203.73 | C32: S3 | E32: closed | F32: in_person | G32: COLEMONT ABU DHABI INSURANCE BROKERS | I32: 0 | J32: Called three times about the delay and no one returned the call. | K32: 46204.48 | L32: 46207.73 | M32: 46206.024 | N32: =IF(K32="","",ROUND((K32-B32)*24,1)) | O32: =IF(M32="","",ROUND(M32-B32,1)) | P32: =IF(M32="","",IF(M32<=L32,"yes","no")) | Q32: charge_correct | R32: 46206.274 | S32: Walked the customer through the job card and photos taken during the work — the additional labour matched what was actually required. Charge stands, explained clearly. | Y32: 46207.941 | AA32: advisor | AB32: Tarek El Sayed
A33: CMP-20260705-9551 | B33: 46208.688 | C33: S3 | E33: resolved | F33: whatsapp | G33: MR-SHAH MOHAMMAD HASAN NAEEM | I33: 0 | J33: Called three times about the delay and no one returned the call. | K33: 46209.021 | L33: 46211.688 | M33: 46210.52 | N33: =IF(K33="","",ROUND((K33-B33)*24,1)) | O33: =IF(M33="","",ROUND(M33-B33,1)) | P33: =IF(M33="","",IF(M33<=L33,"yes","no")) | Q33: partial_refund | R33: 46211.103 | S33: Partial refund agreed — the diagnostic fee should have been waived per policy, the labour charge itself was correct. | T33: method | U33: No standard step existed for confirming a cost change with the customer before extra work began. | V33: QC road test now logged as a required field before a job can be marked ready for pickup. | W33: 46212 | Y33: 46212.687 | AA33: advisor | AB33: Tarek El Sayed
A34: CMP-20260716-5999 | B34: 46219.708 | C34: S2 | E34: resolved | F34: in_person | G34: NASEER SHARIFF AZEEM SHARIF | I34: 137 | J34: Invoice included a diagnostic fee I was told would be waived since I went ahead with the repair. | K34: 46221.583 | L34: 46225.708 | M34: 46227.125 | N34: =IF(K34="","",ROUND((K34-B34)*24,1)) | O34: =IF(M34="","",ROUND(M34-B34,1)) | P34: =IF(M34="","",IF(M34<=L34,"yes","no")) | Q34: goodwill | R34: 46227.417 | S34: No billing error found, but offered a complimentary detail as a goodwill gesture for the inconvenience. | T34: method | U34: No standard step existed for confirming a cost change with the customer before extra work began. | V34: QC road test now logged as a required field before a job can be marked ready for pickup. | W34: 46256 | AA34: manager | AB34: Nadia Khoury
A35: CMP-20260727-3870 | B35: 46230.699 | C35: S2 | E35: closed | F35: phone | G35: MR-PRAVEEN PRASAD CHIRAKKAL CHIRAKK | I35: 458 | J35: The invoice lists a part that was never actually replaced. | K35: 46231.365 | L35: 46236.699 | M35: 46233.869 | N35: =IF(K35="","",ROUND((K35-B35)*24,1)) | O35: =IF(M35="","",ROUND(M35-B35,1)) | P35: =IF(M35="","",IF(M35<=L35,"yes","no")) | Q35: refund_due | R35: 46234.286 | S35: Reviewed the job card against the original estimate — the extra charge was not pre-approved, so a refund was issued for the difference. | T35: measurement | U35: The QC road test was not logged before the vehicle was released. | V35: Added a parts-match check against the job card before issue from stores. | W35: 46259 | Y35: 46236.286 | AA35: manager | AB35: Tarek El Sayed
A36: CMP-20260729-3366 | B36: 46232.365 | C36: S2 | E36: resolved | F36: whatsapp | G36: MR-KANNAN VIJAYAPRAKASH KUNJUPILL | I36: 1120 | J36: Was quoted one price over the phone and charged a higher one at pickup. | K36: 46232.448 | L36: 46238.365 | M36: 46235.202 | N36: =IF(K36="","",ROUND((K36-B36)*24,1)) | O36: =IF(M36="","",ROUND(M36-B36,1)) | P36: =IF(M36="","",IF(M36<=L36,"yes","no")) | Q36: charge_correct | R36: 46235.327 | S36: Estimate covered parts only per the original quote; the labour line was itemised separately from the start. No adjustment due. | Y36: 46236.993 | AA36: manager | AB36: Priya Menon
A37: CMP-20260729-5462 | B37: 46232.459 | C37: S2 | E37: resolved | F37: phone | G37: ARSALA FAZAL RECOVERY | I37: 919 | J37: Charged more than the quoted estimate for the repair — no one called to explain the extra work before it was done. | K37: 46232.584 | L37: 46238.459 | M37: 46239.25 | N37: =IF(K37="","",ROUND((K37-B37)*24,1)) | O37: =IF(M37="","",ROUND(M37-B37,1)) | P37: =IF(M37="","",IF(M37<=L37,"yes","no")) | Q37: partial_refund | R37: 46240.25 | S37: Partial refund agreed — the diagnostic fee should have been waived per policy, the labour charge itself was correct. | AA37: manager | AB37: Nadia Khoury
A38: CMP-20260729-6784 | B38: 46232.699 | C38: S2 | E38: resolved | F38: whatsapp | G38: ABDUL RAHMAN FAHD MOHAMMED | I38: 0 | J38: The service reminder light was never reset after the oil change. | K38: 46233.282 | L38: 46238.699 | M38: 46236.018 | N38: =IF(K38="","",ROUND((K38-B38)*24,1)) | O38: =IF(M38="","",ROUND(M38-B38,1)) | P38: =IF(M38="","",IF(M38<=L38,"yes","no")) | Q38: charge_correct | R38: 46236.435 | S38: Estimate covered parts only per the original quote; the labour line was itemised separately from the start. No adjustment due. | AA38: manager | AB38: Nadia Khoury
A39: CMP-20260729-1889 | B39: 46232.782 | C39: S2 | E39: resolved | F39: in_person | G39: Fadi Karam | I39: 1439 | J39: Charged for more labour hours than the original estimate without being told beforehand. | K39: 46234.032 | L39: 46238.782 | M39: 46238.242 | N39: =IF(K39="","",ROUND((K39-B39)*24,1)) | O39: =IF(M39="","",ROUND(M39-B39,1)) | P39: =IF(M39="","",IF(M39<=L39,"yes","no")) | Q39: goodwill | R39: 46238.7 | S39: Free re-check booked at no charge and a discount applied to the next visit as a gesture of goodwill. | Y39: 46240.45 | AA39: manager | AB39: Workshop Manager
A40: CMP-20260731-6473 | B40: 46234.552 | C40: S3 | E40: closed | F40: in_person | G40: RENJU GEORGE | I40: 0 | J40: Was promised a courtesy car and none was available on the day. | K40: 46236.135 | L40: 46237.552 | M40: 46236.893 | N40: =IF(K40="","",ROUND((K40-B40)*24,1)) | O40: =IF(M40="","",ROUND(M40-B40,1)) | P40: =IF(M40="","",IF(M40<=L40,"yes","no")) | Q40: goodwill | R40: 46237.56 | S40: No billing error found, but offered a complimentary detail as a goodwill gesture for the inconvenience. | Y40: 46238.56 | AA40: advisor | AB40: Tarek El Sayed
...

Sheet Year Summary
A1: Pioneer Car Service Center — Complaints, October 2025 to September 2026
A2: Rolling twelve months. September 2026 is a partial month. See the Notes sheet before reporting these figures.
A4: Headline
A5: Complaints logged | B5: =COUNTA(Complaints!$A$2:$A$55)
A6: Still open or investigating | B6: =COUNTIF(Complaints!$E$2:$E$55,"open")+COUNTIF(Complaints!$E$2:$E$55,"investigating")
A7: Resolved or closed | B7: =COUNTIF(Complaints!$E$2:$E$55,"resolved")+COUNTIF(Complaints!$E$2:$E$55,"closed")
A8: Repeat complaints | B8: =COUNTIF(Complaints!$D$2:$D$55,"yes")
A9: Mean hours to acknowledge | B9: =ROUND(AVERAGE(Complaints!$N$2:$N$55),1)
A10: Mean days to resolve | B10: =ROUND(AVERAGE(Complaints!$O$2:$O$55),1)
A11: Resolved within target | B11: =IF(COUNTIF(Complaints!$P$2:$P$55,"yes")+COUNTIF(Complaints!$P$2:$P$55,"no")=0,"",ROUND(COUNTIF(Complaints!$P$2:$P$55,"yes")/(COUNTIF(Complaints!$P$2:$P$55,"yes")+COUNTIF(Complaints!$P$2:$P$55,"no"))*100,1))
A12: Total amount in dispute (AED) | B12: =ROUND(SUM(Complaints!$I$2:$I$55),2)
A14: By month
A15: Month | B15: Logged | C15: S1 | D15: S2 | E15: S3 | F15: Within target
A16: Oct 2025 | B16: =COUNTIFS(Complaints!$B$2:$B$55,">="&$G16,Complaints!$B$2:$B$55,"<"&$H16) | C16: =COUNTIFS(Complaints!$B$2:$B$55,">="&$G16,Complaints!$B$2:$B$55,"<"&$H16,Complaints!$C$2:$C$55,"S1") | D16: =COUNTIFS(Complaints!$B$2:$B$55,">="&$G16,Complaints!$B$2:$B$55,"<"&$H16,Complaints!$C$2:$C$55,"S2") | E16: =COUNTIFS(Complaints!$B$2:$B$55,">="&$G16,Complaints!$B$2:$B$55,"<"&$H16,Complaints!$C$2:$C$55,"S3") | F16: =IF(COUNTIFS(Complaints!$B$2:$B$55,">="&$G16,Complaints!$B$2:$B$55,"<"&$H16,Complaints!$P$2:$P$55,"yes")+COUNTIFS(Complaints!$B$2:$B$55,">="&$G16,Complaints!$B$2:$B$55,"<"&$H16,Complaints!$P$2:$P$55,"no")=0,"",ROUND(COUNTIFS(Complaints!$B$2:$B$55,">="&$G16,Complaints!$B$2:$B$55,"<"&$H16,Complaints!$P$2:$P$55,"yes")/(COUNTIFS(Complaints!$B$2:$B$55,">="&$G16,Complaints!$B$2:$B$55,"<"&$H16,Complaints!$P$2:$P$55,"yes")+COUNTIFS(Complaints!$B$2:$B$55,">="&$G16,Complaints!$B$2:$B$55,"<"&$H16,Complaints!$P$2:$P$55,"no"))*100,0)) | G16: 45931 | H16: 45962
A17: Nov 2025 | B17: =COUNTIFS(Complaints!$B$2:$B$55,">="&$G17,Complaints!$B$2:$B$55,"<"&$H17) | C17: =COUNTIFS(Complaints!$B$2:$B$55,">="&$G17,Complaints!$B$2:$B$55,"<"&$H17,Complaints!$C$2:$C$55,"S1") | D17: =COUNTIFS(Complaints!$B$2:$B$55,">="&$G17,Complaints!$B$2:$B$55,"<"&$H17,Complaints!$C$2:$C$55,"S2") | E17: =COUNTIFS(Complaints!$B$2:$B$55,">="&$G17,Complaints!$B$2:$B$55,"<"&$H17,Complaints!$C$2:$C$55,"S3") | F17: =IF(COUNTIFS(Complaints!$B$2:$B$55,">="&$G17,Complaints!$B$2:$B$55,"<"&$H17,Complaints!$P$2:$P$55,"yes")+COUNTIFS(Complaints!$B$2:$B$55,">="&$G17,Complaints!$B$2:$B$55,"<"&$H17,Complaints!$P$2:$P$55,"no")=0,"",ROUND(COUNTIFS(Complaints!$B$2:$B$55,">="&$G17,Complaints!$B$2:$B$55,"<"&$H17,Complaints!$P$2:$P$55,"yes")/(COUNTIFS(Complaints!$B$2:$B$55,">="&$G17,Complaints!$B$2:$B$55,"<"&$H17,Complaints!$P$2:$P$55,"yes")+COUNTIFS(Complaints!$B$2:$B$55,">="&$G17,Complaints!$B$2:$B$55,"<"&$H17,Complaints!$P$2:$P$55,"no"))*100,0)) | G17: 45962 | H17: 45992
A18: Dec 2025 | B18: =COUNTIFS(Complaints!$B$2:$B$55,">="&$G18,Complaints!$B$2:$B$55,"<"&$H18) | C18: =COUNTIFS(Complaints!$B$2:$B$55,">="&$G18,Complaints!$B$2:$B$55,"<"&$H18,Complaints!$C$2:$C$55,"S1") | D18: =COUNTIFS(Complaints!$B$2:$B$55,">="&$G18,Complaints!$B$2:$B$55,"<"&$H18,Complaints!$C$2:$C$55,"S2") | E18: =COUNTIFS(Complaints!$B$2:$B$55,">="&$G18,Complaints!$B$2:$B$55,"<"&$H18,Complaints!$C$2:$C$55,"S3") | F18: =IF(COUNTIFS(Complaints!$B$2:$B$55,">="&$G18,Complaints!$B$2:$B$55,"<"&$H18,Complaints!$P$2:$P$55,"yes")+COUNTIFS(Complaints!$B$2:$B$55,">="&$G18,Complaints!$B$2:$B$55,"<"&$H18,Complaints!$P$2:$P$55,"no")=0,"",ROUND(COUNTIFS(Complaints!$B$2:$B$55,">="&$G18,Complaints!$B$2:$B$55,"<"&$H18,Complaints!$P$2:$P$55,"yes")/(COUNTIFS(Complaints!$B$2:$B$55,">="&$G18,Complaints!$B$2:$B$55,"<"&$H18,Complaints!$P$2:$P$55,"yes")+COUNTIFS(Complaints!$B$2:$B$55,">="&$G18,Complaints!$B$2:$B$55,"<"&$H18,Complaints!$P$2:$P$55,"no"))*100,0)) | G18: 45992 | H18: 46023
A19: Jan 2026 | B19: =COUNTIFS(Complaints!$B$2:$B$55,">="&$G19,Complaints!$B$2:$B$55,"<"&$H19) | C19: =COUNTIFS(Complaints!$B$2:$B$55,">="&$G19,Complaints!$B$2:$B$55,"<"&$H19,Complaints!$C$2:$C$55,"S1") | D19: =COUNTIFS(Complaints!$B$2:$B$55,">="&$G19,Complaints!$B$2:$B$55,"<"&$H19,Complaints!$C$2:$C$55,"S2") | E19: =COUNTIFS(Complaints!$B$2:$B$55,">="&$G19,Complaints!$B$2:$B$55,"<"&$H19,Complaints!$C$2:$C$55,"S3") | F19: =IF(COUNTIFS(Complaints!$B$2:$B$55,">="&$G19,Complaints!$B$2:$B$55,"<"&$H19,Complaints!$P$2:$P$55,"yes")+COUNTIFS(Complaints!$B$2:$B$55,">="&$G19,Complaints!$B$2:$B$55,"<"&$H19,Complaints!$P$2:$P$55,"no")=0,"",ROUND(COUNTIFS(Complaints!$B$2:$B$55,">="&$G19,Complaints!$B$2:$B$55,"<"&$H19,Complaints!$P$2:$P$55,"yes")/(COUNTIFS(Complaints!$B$2:$B$55,">="&$G19,Complaints!$B$2:$B$55,"<"&$H19,Complaints!$P$2:$P$55,"yes")+COUNTIFS(Complaints!$B$2:$B$55,">="&$G19,Complaints!$B$2:$B$55,"<"&$H19,Complaints!$P$2:$P$55,"no"))*100,0)) | G19: 46023 | H19: 46054
A20: Feb 2026 | B20: =COUNTIFS(Complaints!$B$2:$B$55,">="&$G20,Complaints!$B$2:$B$55,"<"&$H20) | C20: =COUNTIFS(Complaints!$B$2:$B$55,">="&$G20,Complaints!$B$2:$B$55,"<"&$H20,Complaints!$C$2:$C$55,"S1") | D20: =COUNTIFS(Complaints!$B$2:$B$55,">="&$G20,Complaints!$B$2:$B$55,"<"&$H20,Complaints!$C$2:$C$55,"S2") | E20: =COUNTIFS(Complaints!$B$2:$B$55,">="&$G20,Complaints!$B$2:$B$55,"<"&$H20,Complaints!$C$2:$C$55,"S3") | F20: =IF(COUNTIFS(Complaints!$B$2:$B$55,">="&$G20,Complaints!$B$2:$B$55,"<"&$H20,Complaints!$P$2:$P$55,"yes")+COUNTIFS(Complaints!$B$2:$B$55,">="&$G20,Complaints!$B$2:$B$55,"<"&$H20,Complaints!$P$2:$P$55,"no")=0,"",ROUND(COUNTIFS(Complaints!$B$2:$B$55,">="&$G20,Complaints!$B$2:$B$55,"<"&$H20,Complaints!$P$2:$P$55,"yes")/(COUNTIFS(Complaints!$B$2:$B$55,">="&$G20,Complaints!$B$2:$B$55,"<"&$H20,Complaints!$P$2:$P$55,"yes")+COUNTIFS(Complaints!$B$2:$B$55,">="&$G20,Complaints!$B$2:$B$55,"<"&$H20,Complaints!$P$2:$P$55,"no"))*100,0)) | G20: 46054 | H20: 46082
A21: Mar 2026 | B21: =COUNTIFS(Complaints!$B$2:$B$55,">="&$G21,Complaints!$B$2:$B$55,"<"&$H21) | C21: =COUNTIFS(Complaints!$B$2:$B$55,">="&$G21,Complaints!$B$2:$B$55,"<"&$H21,Complaints!$C$2:$C$55,"S1") | D21: =COUNTIFS(Complaints!$B$2:$B$55,">="&$G21,Complaints!$B$2:$B$55,"<"&$H21,Complaints!$C$2:$C$55,"S2") | E21: =COUNTIFS(Complaints!$B$2:$B$55,">="&$G21,Complaints!$B$2:$B$55,"<"&$H21,Complaints!$C$2:$C$55,"S3") | F21: =IF(COUNTIFS(Complaints!$B$2:$B$55,">="&$G21,Complaints!$B$2:$B$55,"<"&$H21,Complaints!$P$2:$P$55,"yes")+COUNTIFS(Complaints!$B$2:$B$55,">="&$G21,Complaints!$B$2:$B$55,"<"&$H21,Complaints!$P$2:$P$55,"no")=0,"",ROUND(COUNTIFS(Complaints!$B$2:$B$55,">="&$G21,Complaints!$B$2:$B$55,"<"&$H21,Complaints!$P$2:$P$55,"yes")/(COUNTIFS(Complaints!$B$2:$B$55,">="&$G21,Complaints!$B$2:$B$55,"<"&$H21,Complaints!$P$2:$P$55,"yes")+COUNTIFS(Complaints!$B$2:$B$55,">="&$G21,Complaints!$B$2:$B$55,"<"&$H21,Complaints!$P$2:$P$55,"no"))*100,0)) | G21: 46082 | H21: 46113
A22: Apr 2026 | B22: =COUNTIFS(Complaints!$B$2:$B$55,">="&$G22,Complaints!$B$2:$B$55,"<"&$H22) | C22: =COUNTIFS(Complaints!$B$2:$B$55,">="&$G22,Complaints!$B$2:$B$55,"<"&$H22,Complaints!$C$2:$C$55,"S1") | D22: =COUNTIFS(Complaints!$B$2:$B$55,">="&$G22,Complaints!$B$2:$B$55,"<"&$H22,Complaints!$C$2:$C$55,"S2") | E22: =COUNTIFS(Complaints!$B$2:$B$55,">="&$G22,Complaints!$B$2:$B$55,"<"&$H22,Complaints!$C$2:$C$55,"S3") | F22: =IF(COUNTIFS(Complaints!$B$2:$B$55,">="&$G22,Complaints!$B$2:$B$55,"<"&$H22,Complaints!$P$2:$P$55,"yes")+COUNTIFS(Complaints!$B$2:$B$55,">="&$G22,Complaints!$B$2:$B$55,"<"&$H22,Complaints!$P$2:$P$55,"no")=0,"",ROUND(COUNTIFS(Complaints!$B$2:$B$55,">="&$G22,Complaints!$B$2:$B$55,"<"&$H22,Complaints!$P$2:$P$55,"yes")/(COUNTIFS(Complaints!$B$2:$B$55,">="&$G22,Complaints!$B$2:$B$55,"<"&$H22,Complaints!$P$2:$P$55,"yes")+COUNTIFS(Complaints!$B$2:$B$55,">="&$G22,Complaints!$B$2:$B$55,"<"&$H22,Complaints!$P$2:$P$55,"no"))*100,0)) | G22: 46113 | H22: 46143
A23: May 2026 | B23: =COUNTIFS(Complaints!$B$2:$B$55,">="&$G23,Complaints!$B$2:$B$55,"<"&$H23) | C23: =COUNTIFS(Complaints!$B$2:$B$55,">="&$G23,Complaints!$B$2:$B$55,"<"&$H23,Complaints!$C$2:$C$55,"S1") | D23: =COUNTIFS(Complaints!$B$2:$B$55,">="&$G23,Complaints!$B$2:$B$55,"<"&$H23,Complaints!$C$2:$C$55,"S2") | E23: =COUNTIFS(Complaints!$B$2:$B$55,">="&$G23,Complaints!$B$2:$B$55,"<"&$H23,Complaints!$C$2:$C$55,"S3") | F23: =IF(COUNTIFS(Complaints!$B$2:$B$55,">="&$G23,Complaints!$B$2:$B$55,"<"&$H23,Complaints!$P$2:$P$55,"yes")+COUNTIFS(Complaints!$B$2:$B$55,">="&$G23,Complaints!$B$2:$B$55,"<"&$H23,Complaints!$P$2:$P$55,"no")=0,"",ROUND(COUNTIFS(Complaints!$B$2:$B$55,">="&$G23,Complaints!$B$2:$B$55,"<"&$H23,Complaints!$P$2:$P$55,"yes")/(COUNTIFS(Complaints!$B$2:$B$55,">="&$G23,Complaints!$B$2:$B$55,"<"&$H23,Complaints!$P$2:$P$55,"yes")+COUNTIFS(Complaints!$B$2:$B$55,">="&$G23,Complaints!$B$2:$B$55,"<"&$H23,Complaints!$P$2:$P$55,"no"))*100,0)) | G23: 46143 | H23: 46174
A24: Jun 2026 | B24: =COUNTIFS(Complaints!$B$2:$B$55,">="&$G24,Complaints!$B$2:$B$55,"<"&$H24) | C24: =COUNTIFS(Complaints!$B$2:$B$55,">="&$G24,Complaints!$B$2:$B$55,"<"&$H24,Complaints!$C$2:$C$55,"S1") | D24: =COUNTIFS(Complaints!$B$2:$B$55,">="&$G24,Complaints!$B$2:$B$55,"<"&$H24,Complaints!$C$2:$C$55,"S2") | E24: =COUNTIFS(Complaints!$B$2:$B$55,">="&$G24,Complaints!$B$2:$B$55,"<"&$H24,Complaints!$C$2:$C$55,"S3") | F24: =IF(COUNTIFS(Complaints!$B$2:$B$55,">="&$G24,Complaints!$B$2:$B$55,"<"&$H24,Complaints!$P$2:$P$55,"yes")+COUNTIFS(Complaints!$B$2:$B$55,">="&$G24,Complaints!$B$2:$B$55,"<"&$H24,Complaints!$P$2:$P$55,"no")=0,"",ROUND(COUNTIFS(Complaints!$B$2:$B$55,">="&$G24,Complaints!$B$2:$B$55,"<"&$H24,Complaints!$P$2:$P$55,"yes")/(COUNTIFS(Complaints!$B$2:$B$55,">="&$G24,Complaints!$B$2:$B$55,"<"&$H24,Complaints!$P$2:$P$55,"yes")+COUNTIFS(Complaints!$B$2:$B$55,">="&$G24,Complaints!$B$2:$B$55,"<"&$H24,Complaints!$P$2:$P$55,"no"))*100,0)) | G24: 46174 | H24: 46204
A25: Jul 2026 | B25: =COUNTIFS(Complaints!$B$2:$B$55,">="&$G25,Complaints!$B$2:$B$55,"<"&$H25) | C25: =COUNTIFS(Complaints!$B$2:$B$55,">="&$G25,Complaints!$B$2:$B$55,"<"&$H25,Complaints!$C$2:$C$55,"S1") | D25: =COUNTIFS(Complaints!$B$2:$B$55,">="&$G25,Complaints!$B$2:$B$55,"<"&$H25,Complaints!$C$2:$C$55,"S2") | E25: =COUNTIFS(Complaints!$B$2:$B$55,">="&$G25,Complaints!$B$2:$B$55,"<"&$H25,Complaints!$C$2:$C$55,"S3") | F25: =IF(COUNTIFS(Complaints!$B$2:$B$55,">="&$G25,Complaints!$B$2:$B$55,"<"&$H25,Complaints!$P$2:$P$55,"yes")+COUNTIFS(Complaints!$B$2:$B$55,">="&$G25,Complaints!$B$2:$B$55,"<"&$H25,Complaints!$P$2:$P$55,"no")=0,"",ROUND(COUNTIFS(Complaints!$B$2:$B$55,">="&$G25,Complaints!$B$2:$B$55,"<"&$H25,Complaints!$P$2:$P$55,"yes")/(COUNTIFS(Complaints!$B$2:$B$55,">="&$G25,Complaints!$B$2:$B$55,"<"&$H25,Complaints!$P$2:$P$55,"yes")+COUNTIFS(Complaints!$B$2:$B$55,">="&$G25,Complaints!$B$2:$B$55,"<"&$H25,Complaints!$P$2:$P$55,"no"))*100,0)) | G25: 46204 | H25: 46235
A26: Aug 2026 | B26: =COUNTIFS(Complaints!$B$2:$B$55,">="&$G26,Complaints!$B$2:$B$55,"<"&$H26) | C26: =COUNTIFS(Complaints!$B$2:$B$55,">="&$G26,Complaints!$B$2:$B$55,"<"&$H26,Complaints!$C$2:$C$55,"S1") | D26: =COUNTIFS(Complaints!$B$2:$B$55,">="&$G26,Complaints!$B$2:$B$55,"<"&$H26,Complaints!$C$2:$C$55,"S2") | E26: =COUNTIFS(Complaints!$B$2:$B$55,">="&$G26,Complaints!$B$2:$B$55,"<"&$H26,Complaints!$C$2:$C$55,"S3") | F26: =IF(COUNTIFS(Complaints!$B$2:$B$55,">="&$G26,Complaints!$B$2:$B$55,"<"&$H26,Complaints!$P$2:$P$55,"yes")+COUNTIFS(Complaints!$B$2:$B$55,">="&$G26,Complaints!$B$2:$B$55,"<"&$H26,Complaints!$P$2:$P$55,"no")=0,"",ROUND(COUNTIFS(Complaints!$B$2:$B$55,">="&$G26,Complaints!$B$2:$B$55,"<"&$H26,Complaints!$P$2:$P$55,"yes")/(COUNTIFS(Complaints!$B$2:$B$55,">="&$G26,Complaints!$B$2:$B$55,"<"&$H26,Complaints!$P$2:$P$55,"yes")+COUNTIFS(Complaints!$B$2:$B$55,">="&$G26,Complaints!$B$2:$B$55,"<"&$H26,Complaints!$P$2:$P$55,"no"))*100,0)) | G26: 46235 | H26: 46266
A27: Sep 2026 | B27: =COUNTIFS(Complaints!$B$2:$B$55,">="&$G27,Complaints!$B$2:$B$55,"<"&$H27) | C27: =COUNTIFS(Complaints!$B$2:$B$55,">="&$G27,Complaints!$B$2:$B$55,"<"&$H27,Complaints!$C$2:$C$55,"S1") | D27: =COUNTIFS(Complaints!$B$2:$B$55,">="&$G27,Complaints!$B$2:$B$55,"<"&$H27,Complaints!$C$2:$C$55,"S2") | E27: =COUNTIFS(Complaints!$B$2:$B$55,">="&$G27,Complaints!$B$2:$B$55,"<"&$H27,Complaints!$C$2:$C$55,"S3") | F27: =IF(COUNTIFS(Complaints!$B$2:$B$55,">="&$G27,Complaints!$B$2:$B$55,"<"&$H27,Complaints!$P$2:$P$55,"yes")+COUNTIFS(Complaints!$B$2:$B$55,">="&$G27,Complaints!$B$2:$B$55,"<"&$H27,Complaints!$P$2:$P$55,"no")=0,"",ROUND(COUNTIFS(Complaints!$B$2:$B$55,">="&$G27,Complaints!$B$2:$B$55,"<"&$H27,Complaints!$P$2:$P$55,"yes")/(COUNTIFS(Complaints!$B$2:$B$55,">="&$G27,Complaints!$B$2:$B$55,"<"&$H27,Complaints!$P$2:$P$55,"yes")+COUNTIFS(Complaints!$B$2:$B$55,">="&$G27,Complaints!$B$2:$B$55,"<"&$H27,Complaints!$P$2:$P$55,"no"))*100,0)) | G27: 46266 | H27: 46296
A29: Total | B29: =SUM(B16:B27) | C29: =SUM(C16:C27) | D29: =SUM(D16:D27) | E29: =SUM(E16:E27)
A31: By severity | B31: Count | C31: Share
A32: S1 | B32: =COUNTIF(Complaints!$C$2:$C$55,$A32) | C32: =IF($B$5=0,"",ROUND(B32/$B$5*100,1))
A33: S2 | B33: =COUNTIF(Complaints!$C$2:$C$55,$A33) | C33: =IF($B$5=0,"",ROUND(B33/$B$5*100,1))
A34: S3 | B34: =COUNTIF(Complaints!$C$2:$C$55,$A34) | C34: =IF($B$5=0,"",ROUND(B34/$B$5*100,1))
A36: By status | B36: Count | C36: Share
A37: open | B37: =COUNTIF(Complaints!$E$2:$E$55,$A37) | C37: =IF($B$5=0,"",ROUND(B37/$B$5*100,1))
A38: investigating | B38: =COUNTIF(Complaints!$E$2:$E$55,$A38) | C38: =IF($B$5=0,"",ROUND(B38/$B$5*100,1))
A39: resolved | B39: =COUNTIF(Complaints!$E$2:$E$55,$A39) | C39: =IF($B$5=0,"",ROUND(B39/$B$5*100,1))
A40: closed | B40: =COUNTIF(Complaints!$E$2:$E$55,$A40) | C40: =IF($B$5=0,"",ROUND(B40/$B$5*100,1))
A42: By intake channel | B42: Count | C42: Share
A43: in_person | B43: =COUNTIF(Complaints!$F$2:$F$55,$A43) | C43: =IF($B$5=0,"",ROUND(B43/$B$5*100,1))
A44: phone | B44: =COUNTIF(Complaints!$F$2:$F$55,$A44) | C44: =IF($B$5=0,"",ROUND(B44/$B$5*100,1))
A45: email | B45: =COUNTIF(Complaints!$F$2:$F$55,$A45) | C45: =IF($B$5=0,"",ROUND(B45/$B$5*100,1))
A46: whatsapp | B46: =COUNTIF(Complaints!$F$2:$F$55,$A46) | C46: =IF($B$5=0,"",ROUND(B46/$B$5*100,1))
...

Sheet Notes
A1: Pioneer Car Service Center — complaints, October 2025 to September 2026
A3: What this is
A4: All 54 complaint records held for the workshop across the rolling twelve months, exported from the disputes table that the Complaints page and the Customer Experience dashboard read live. Columns follow the severity workflow: severity, target date, acknowledgement, outcome, root cause, corrective action and customer confirmation.
A6: This is generated demonstration data, not real complaints
A7: The cases, amounts and narratives were generated to give the dashboards a believable year of history. They are not real customer complaints and must not be reported as the workshop's actual complaint record. The customer names attached to them ARE real customers from the system, because the seed links to existing records so the joins work — so a case here pairs a real name with an invented complaint. Treat any individual row as fiction.
A9: The volume taper is deliberate
A10: Roughly one complaint a month a year ago rising to nine last month. That reflects a CX programme that logged almost nothing at the start and now captures most of what comes in. Read as a quality trend it says the opposite of what it means.
A12: September 2026 is incomplete
A13: The month was still running when this was exported, so its count is lower than a finished month and should not be compared with the eleven before it.
A15: How the targets work
A16: Each case gets a response target from its severity — S1 two working days, S2 five, S3 three — computed on creation, skipping Fridays. Within target compares the resolved date against that case's own target. Cases still open count as neither met nor missed, so the compliance rate is a share of decided cases.
A18: Regenerating it
... A21: --clean removes exactly the rows the previous run created, tracked in scripts/data/.seed-complaints-ids.json. Rows from a run whose tracking file was lost cannot be cleaned automatically.
